<?xml version="1.0" ?>
<!-- =================================================================================== -->
<!-- |    This document was autogenerated by xacro from model.xacro.urdf               | -->
<!-- |    EDITING THIS FILE BY HAND IS NOT RECOMMENDED                                 | -->
<!-- =================================================================================== -->
<robot name="traxxas" xmlns:xacro="http://ros.org/wiki/xacro">
  <!--- Surface properties must come first? -->
  <gazebo reference="front_left_wheel">
    <mu1>0.9</mu1>
    <mu2>0.9</mu2>
    <minDepth>0.005</minDepth>
    <kp>1e8</kp>
  </gazebo>
  <gazebo reference="front_right_wheel">
    <mu1>0.9</mu1>
    <mu2>0.9</mu2>
    <minDepth>0.005</minDepth>
    <kp>1e8</kp>
  </gazebo>
  <gazebo reference="rear_left_wheel">
    <mu1>0.9</mu1>
    <mu2>0.9</mu2>
    <minDepth>0.005</minDepth>
    <kp>1e8</kp>
  </gazebo>
  <gazebo reference="rear_right_wheel">
    <mu1>0.9</mu1>
    <mu2>0.9</mu2>
    <minDepth>0.005</minDepth>
    <kp>1e8</kp>
  </gazebo>
  <!--- Links -->
  <link name="base_link">
    <inertial>
      <mass value="1"/>
      <inertia ixx="0.001" ixy="0.0" ixz="0.0" iyy="0.001" iyz="0.0" izz="0.001"/>
    </inertial>
  </link>
  <link name="steering_wheel">
    <inertial>
      <mass value="1.0"/>
      <inertia ixx="0.14583300" ixy="0.0" ixz="0.0" iyy="0.14583300" iyz="0.0" izz="0.125"/>
    </inertial>
  </link>
  <link name="chassis">
    <visual>
      <origin rpy="0 0 0" xyz="0 0 -0.07"/>
      <geometry>
        <mesh filename="package://traxxas_ros_gazebo/meshes/body.obj" scale="0.1 0.1 0.1"/>
      </geometry>
    </visual>
    <collision name="chassis">
      <origin rpy="0 0 0" xyz="0 0.07 0"/>
      <geometry>
        <box size="0.3 0.65 0.15"/>
      </geometry>
    </collision>
    <inertial>
      <mass value="13.0"/>
      <origin rpy="0 0 0" xyz="0 0 0.48"/>
      <inertia ixx="2581.13354740" ixy="0.0" ixz="0.0" iyy="591.30846112" iyz="0.0" izz="2681.95008628"/>
    </inertial>
    <origin rpy="0 0 0" xyz="0 0 0"/>
  </link>
  <link name="fl_axle">
    <inertial>
      <mass value="1"/>
      <origin xyz="0 0 1"/>
      <inertia ixx="0.004" ixy="0.0" ixz="0.0" iyy="0.004" iyz="0.0" izz="0.004"/>
    </inertial>
  </link>
  <link name="fr_axle">
    <inertial>
      <mass value="1"/>
      <origin xyz="0 0 1"/>
      <inertia ixx="0.004" ixy="0.0" ixz="0.0" iyy="0.004" iyz="0.0" izz="0.004"/>
    </inertial>
  </link>
  <link name="front_left_wheel">
    <inertial>
      <mass value="11"/>
      <origin xyz="0 0 0"/>
      <inertia ixx="0.58631238" ixy="0.0" ixz="0.0" iyy="0.33552910" iyz="0.0" izz="0.33552910"/>
    </inertial>
    <collision name="front_left_wheel_collision">
      <geometry>
        <cylinder length="0.042" radius="0.054"/>
      </geometry>
      <origin rpy="0 3.14159265359 0" xyz="0 0 0.0025"/>
    </collision>
    <visual>
      <origin rpy="0 3.14159265359 0" xyz="0 0 0.0025"/>
      <geometry>
        <mesh filename="package://traxxas_ros_gazebo/meshes/wheel.obj" scale="0.1 0.1 0.1"/>
      </geometry>
    </visual>
  </link>
  <link name="front_right_wheel">
    <inertial>
      <mass value="11"/>
      <origin xyz="0 0 0"/>
      <inertia ixx="0.58631238" ixy="0.0" ixz="0.0" iyy="0.33552910" iyz="0.0" izz="0.33552910"/>
    </inertial>
    <collision name="front_right_wheel_collision">
      <geometry>
        <cylinder length="0.042" radius="0.054"/>
      </geometry>
      <origin rpy="0 0 0" xyz="0 0 0.0025"/>
    </collision>
    <visual>
      <origin rpy="0 0 0" xyz="0 0 0.0025"/>
      <geometry>
        <mesh filename="package://traxxas_ros_gazebo/meshes/wheel.obj" scale="0.1 0.1 0.1"/>
      </geometry>
    </visual>
  </link>
  <link name="rear_left_wheel">
    <inertial>
      <mass value="11"/>
      <origin xyz="0 0 0"/>
      <inertia ixx="0.58631238" ixy="0.0" ixz="0.0" iyy="0.33552910" iyz="0.0" izz="0.33552910"/>
    </inertial>
    <collision name="rear_left_wheel_collision">
      <geometry>
        <cylinder length="0.042" radius="0.054"/>
      </geometry>
      <origin rpy="0 3.14159265359 0" xyz="0 0 0.0025"/>
    </collision>
    <visual>
      <origin rpy="0 3.14159265359 0" xyz="0 0 0.0025"/>
      <geometry>
        <mesh filename="package://traxxas_ros_gazebo/meshes/wheel.obj" scale="0.1 0.1 0.1"/>
      </geometry>
    </visual>
  </link>
  <link name="rear_right_wheel">
    <inertial>
      <mass value="11"/>
      <origin xyz="0 0 0"/>
      <inertia ixx="0.58631238" ixy="0.0" ixz="0.0" iyy="0.33552910" iyz="0.0" izz="0.33552910"/>
    </inertial>
    <collision name="rear_right_wheel_collision">
      <geometry>
        <cylinder length="0.042" radius="0.054"/>
      </geometry>
      <origin rpy="0 0 0" xyz="0 0 0.0025"/>
    </collision>
    <visual>
      <origin rpy="0 0 0" xyz="0 0 0.0025"/>
      <geometry>
        <mesh filename="package://traxxas_ros_gazebo/meshes/wheel.obj" scale="0.1 0.1 0.1"/>
      </geometry>
    </visual>
  </link>
  <!--- Joints -->
  <joint name="base_link_connection" type="fixed">
    <parent link="base_link"/>
    <child link="chassis"/>
    <origin rpy="0 0 0" xyz="0 0 0"/>
    <axis xyz="1 0 0"/>
  </joint>
  <joint name="steering_joint" type="revolute">
    <origin rpy="0 0 0" xyz="0 0 0.03"/>
    <parent link="chassis"/>
    <child link="steering_wheel"/>
    <axis xyz="0 0 1"/>
    <limit effort="10000000" lower="-3.14159265359" upper="3.14159265359" velocity="1000000"/>
  </joint>
  <joint name="front_left_steer_joint" type="revolute">
    <origin rpy="0 0 0" xyz="-0.12 0.2 -0.02"/>
    <parent link="chassis"/>
    <child link="fl_axle"/>
    <axis xyz="0 0 1"/>
    <limit effort="10000000" lower="-0.523598775598" upper="0.523598775598" velocity="1000000"/>
  </joint>
  <joint name="front_right_steer_joint" type="revolute">
    <origin rpy="0 0 0" xyz="0.12 0.2 -0.02"/>
    <parent link="chassis"/>
    <child link="fr_axle"/>
    <axis xyz="0 0 1"/>
    <limit effort="10000000" lower="-0.523598775598" upper="0.523598775598" velocity="1000000"/>
  </joint>
  <joint name="front_left_wheel_joint" type="continuous">
    <parent link="fl_axle"/>
    <child link="front_left_wheel"/>
    <origin rpy="0 0 0" xyz="0 0 0"/>
    <axis xyz="1 0 0"/>
  </joint>
  <joint name="front_right_wheel_joint" type="continuous">
    <parent link="fr_axle"/>
    <child link="front_right_wheel"/>
    <origin rpy="0 0 0" xyz="0 0 0"/>
    <axis xyz="1 0 0"/>
  </joint>
  <joint name="rear_left_wheel_joint" type="continuous">
    <parent link="chassis"/>
    <child link="rear_left_wheel"/>
    <origin rpy="0 0 0" xyz="-0.12 -0.175 -0.02"/>
    <axis xyz="1 0 0"/>
  </joint>
  <joint name="rear_right_wheel_joint" type="continuous">
    <parent link="chassis"/>
    <child link="rear_right_wheel"/>
    <origin rpy="0 0 0" xyz="0.12 -0.175 -0.02"/>
    <axis xyz="1 0 0"/>
  </joint>
  <!-- Sensor links and fixed joints -->
  <link name="center_laser_link">
    <inertial>
      <mass value="1"/>
      <inertia ixx="0.001" ixy="0.0" ixz="0.0" iyy="0.001" iyz="0.0" izz="0.001"/>
    </inertial>
  </link>
  <joint name="center_laser_joint" type="fixed">
    <parent link="chassis"/>
    <child link="center_laser_link"/>
    <origin rpy="0 0 -1.57079632679" xyz="0 0.2 0.03"/>
  </joint>
  <gazebo reference="base_link_connection">
    <disableFixedJointLumping>true</disableFixedJointLumping>
  </gazebo>
  <link name="front_camera_link">
    <inertial>
      <mass value="1"/>
      <inertia ixx="0.001" ixy="0.0" ixz="0.0" iyy="0.001" iyz="0.0" izz="0.001"/>
    </inertial>
  </link>
  <joint name="front_camera_joint" type="fixed">
    <parent link="chassis"/>
    <child link="front_camera_link"/>
    <origin rpy="0 0 -1.57079632679" xyz="0 0.2 0.03"/>
  </joint>
  <gazebo>
    <plugin filename="libTraxxasPlugin.so" name="pruis__drive">
      <chassis>chassis</chassis>
      <front_left_wheel>front_left_wheel_joint</front_left_wheel>
      <front_right_wheel>front_right_wheel_joint</front_right_wheel>
      <front_left_wheel_steering>front_left_steer_joint</front_left_wheel_steering>
      <front_right_wheel_steering>front_right_steer_joint</front_right_wheel_steering>
      <back_left_wheel>rear_left_wheel_joint</back_left_wheel>
      <back_right_wheel>rear_right_wheel_joint</back_right_wheel>
      <steering_wheel>steering_joint</steering_wheel>
      <chassis_aero_force_gain>0.63045</chassis_aero_force_gain>
      <front_torque>859.4004393000001</front_torque>
      <back_torque>0</back_torque>
      <front_brake_torque>1031.28052716</front_brake_torque>
      <back_brake_torque>687.5203514400001</back_brake_torque>
      <max_speed>37.998337013956565</max_speed>
      <min_gas_flow>8.981854013171626e-05</min_gas_flow>
      <gas_efficiency>0.371</gas_efficiency>
      <battery_charge_watt_hours>291</battery_charge_watt_hours>
      <battery_discharge_watt_hours>214</battery_discharge_watt_hours>
      <max_steer>0.6458</max_steer>
      <flwheel_steering_p_gain>1e4</flwheel_steering_p_gain>
      <frwheel_steering_p_gain>1e4</frwheel_steering_p_gain>
      <flwheel_steering_i_gain>0</flwheel_steering_i_gain>
      <frwheel_steering_i_gain>0</frwheel_steering_i_gain>
      <flwheel_steering_d_gain>3e2</flwheel_steering_d_gain>
      <frwheel_steering_d_gain>3e2</frwheel_steering_d_gain>
    </plugin>
  </gazebo>
  <gazebo>
    <plugin filename="libgazebo_ros_joint_state_publisher.so" name="joint_state_publisher">
      <!-- <robotNamespace>/traxxas</robotNamespace> -->
      <jointName>rear_right_wheel_joint, rear_left_wheel_joint, front_right_wheel_joint, front_left_wheel_joint, front_right_steer_joint, front_left_steer_joint, steering_joint</jointName>
      <updateRate>100.0</updateRate>
      <alwaysOn>true</alwaysOn>
    </plugin>
  </gazebo>
  <gazebo>
    <plugin filename="libgazebo_ros_p3d.so" name="p3d">
      <!-- <robotNamespace>/traxxas</robotNamespace> -->
      <bodyName>base_link</bodyName>
      <topicName>base_pose_ground_truth</topicName>
      <frameName>map</frameName>
      <updateRate>100.0</updateRate>
    </plugin>
  </gazebo>
  <gazebo reference="center_laser_link">
    <sensor name="center_laser_sensor" type="ray">
      <ray>
        <scan>
          <horizontal>
            <samples>512</samples>
            <resolution>1</resolution>
            <min_angle>-3.14</min_angle>
            <max_angle>3.14</max_angle>
          </horizontal>
          <vertical>
            <samples>16</samples>
            <min_angle>-0.1</min_angle>
            <max_angle>-0.35</max_angle>
          </vertical>
        </scan>
        <range>
          <min>0.2</min>
          <max>30</max>
          <resolution>0.01</resolution>
        </range>
      </ray>
      <plugin filename="libgazebo_ros_custom_block_laser_plugin.so" name="center_laser">
        <topicName>/traxxas/center_laser/scan</topicName>
        <frameName>center_laser_link</frameName>
      </plugin>
      <always_on>1</always_on>
      <update_rate>30</update_rate>
      <visualize>0</visualize>
    </sensor>
  </gazebo>
  <gazebo reference="front_camera_link">
    <sensor name="front_camera_sensor" type="camera">
      <update_rate>30.0</update_rate>
      <camera name="front_camera">
        <horizontal_fov>1.3962634</horizontal_fov>
        <image>
          <width>800</width>
          <height>800</height>
          <format>R8G8B8</format>
        </image>
        <clip>
          <near>0.02</near>
          <far>300</far>
        </clip>
        <noise>
          <type>gaussian</type>
          <mean>0.0</mean>
          <stddev>0.007</stddev>
        </noise>
      </camera>
      <plugin filename="libgazebo_ros_camera.so" name="front_camera_controller">
        <alwaysOn>false</alwaysOn>
        <updateRate>0.0</updateRate>
        <cameraName>/traxxas/front_camera</cameraName>
        <imageTopicName>image_raw</imageTopicName>
        <cameraInfoTopicName>/traxxas/front_camera_info</cameraInfoTopicName>
        <frameName>camera_link</frameName>
        <hackBaseline>0.07</hackBaseline>
        <distortionK1>0.0</distortionK1>
        <distortionK2>0.0</distortionK2>
        <distortionK3>0.0</distortionK3>
        <distortionT1>0.0</distortionT1>
        <distortionT2>0.0</distortionT2>
      </plugin>
    </sensor>
  </gazebo>
</robot>

